Traceback (most recent call last):
  File "/Users/melwalsh/anaconda3/lib/python3.11/site-packages/jupyter_cache/executors/utils.py", line 58, in single_nb_execution
    executenb(
  File "/Users/melwalsh/anaconda3/lib/python3.11/site-packages/nbclient/client.py", line 1305, in execute
    return NotebookClient(nb=nb, resources=resources, km=km, **kwargs).execute()
           ^^^^^^^^^^^^^^^^^^^^^^^^^^^^^^^^^^^^^^^^^^^^^^^^^^^^^^^^^^^^^^^^^^^^^
  File "/Users/melwalsh/anaconda3/lib/python3.11/site-packages/jupyter_core/utils/__init__.py", line 173, in wrapped
    return loop.run_until_complete(inner)
           ^^^^^^^^^^^^^^^^^^^^^^^^^^^^^^
  File "/Users/melwalsh/anaconda3/lib/python3.11/asyncio/base_events.py", line 654, in run_until_complete
    return future.result()
           ^^^^^^^^^^^^^^^
  File "/Users/melwalsh/anaconda3/lib/python3.11/site-packages/nbclient/client.py", line 705, in async_execute
    await self.async_execute_cell(
  File "/Users/melwalsh/anaconda3/lib/python3.11/site-packages/nbclient/client.py", line 1058, in async_execute_cell
    await self._check_raise_for_error(cell, cell_index, exec_reply)
  File "/Users/melwalsh/anaconda3/lib/python3.11/site-packages/nbclient/client.py", line 914, in _check_raise_for_error
    raise CellExecutionError.from_cell_and_msg(cell, exec_reply_content)
nbclient.exceptions.CellExecutionError: An error occurred while executing the following cell:
------------------
path_to_tsv = "/path/to/the_file.tsv"
id_column_name = 'recordid'
user_agent = 'YOUR PROJECT NAME HERE'
pause_between_req = 0

import pandas as pd
import requests
import time
import pymarc
import io

------------------


[0;31m---------------------------------------------------------------------------[0m
[0;31mModuleNotFoundError[0m                       Traceback (most recent call last)
Cell [0;32mIn[1], line 9[0m
[1;32m      7[0m [38;5;28;01mimport[39;00m [38;5;21;01mrequests[39;00m
[1;32m      8[0m [38;5;28;01mimport[39;00m [38;5;21;01mtime[39;00m
[0;32m----> 9[0m [38;5;28;01mimport[39;00m [38;5;21;01mpymarc[39;00m
[1;32m     10[0m [38;5;28;01mimport[39;00m [38;5;21;01mio[39;00m

[0;31mModuleNotFoundError[0m: No module named 'pymarc'

